<?xml version="1.0" encoding="UTF-8"?>
<testng-results total="1" passed="0" failed="1" skipped="0">
  <reporter-output>
  </reporter-output>
  <suite started-at="2018-12-24T19:02:08Z" name="Default suite" finished-at="2018-12-24T19:02:08Z" duration-ms="71">
    <groups>
    </groups>
    <test started-at="2018-12-24T19:02:08Z" name="Default test" finished-at="2018-12-24T19:02:08Z" duration-ms="71">
      <class name="testing.AssertDemoFailed">
        <test-method signature="MEthod1()[pri:0, instance:testing.AssertDemoFailed@24269709]" started-at="2018-12-25T00:32:08Z" name="MEthod1" finished-at="2018-12-25T00:32:08Z" duration-ms="34" status="FAIL">
          <exception class="java.lang.AssertionError">
            <message>
              <![CDATA[expected [Saxena] but found [Akash]]]>
            </message>
            <full-stacktrace>
              <![CDATA[java.lang.AssertionError: expected [Saxena] but found [Akash]
	at org.testng.Assert.fail(Assert.java:94)
	at org.testng.Assert.failNotEquals(Assert.java:494)
	at org.testng.Assert.assertEquals(Assert.java:123)
	at org.testng.Assert.assertEquals(Assert.java:176)
	at org.testng.Assert.assertEquals(Assert.java:186)
	at testing.AssertDemoFailed.MEthod1(AssertDemoFailed.java:16)
	at java.base/jdk.internal.reflect.NativeMethodAccessorImpl.invoke0(Native Method)
	at java.base/jdk.internal.reflect.NativeMethodAccessorImpl.invoke(Unknown Source)
	at java.base/jdk.internal.reflect.DelegatingMethodAccessorImpl.invoke(Unknown Source)
	at java.base/java.lang.reflect.Method.invoke(Unknown Source)
	at org.testng.internal.MethodInvocationHelper.invokeMethod(MethodInvocationHelper.java:84)
	at org.testng.internal.Invoker.invokeMethod(Invoker.java:714)
	at org.testng.internal.Invoker.invokeTestMethod(Invoker.java:901)
	at org.testng.internal.Invoker.invokeTestMethods(Invoker.java:1231)
	at org.testng.internal.TestMethodWorker.invokeTestMethods(TestMethodWorker.java:127)
	at org.testng.internal.TestMethodWorker.run(TestMethodWorker.java:111)
	at org.testng.TestRunner.privateRun(TestRunner.java:767)
	at org.testng.TestRunner.run(TestRunner.java:617)
	at org.testng.SuiteRunner.runTest(SuiteRunner.java:334)
	at org.testng.SuiteRunner.runSequentially(SuiteRunner.java:329)
	at org.testng.SuiteRunner.privateRun(SuiteRunner.java:291)
	at org.testng.SuiteRunner.run(SuiteRunner.java:240)
	at org.testng.SuiteRunnerWorker.runSuite(SuiteRunnerWorker.java:52)
	at org.testng.SuiteRunnerWorker.run(SuiteRunnerWorker.java:86)
	at org.testng.TestNG.runSuitesSequentially(TestNG.java:1224)
	at org.testng.TestNG.runSuitesLocally(TestNG.java:1149)
	at org.testng.TestNG.run(TestNG.java:1057)
	at org.testng.remote.AbstractRemoteTestNG.run(AbstractRemoteTestNG.java:114)
	at org.testng.remote.RemoteTestNG.initAndRun(RemoteTestNG.java:251)
	at org.testng.remote.RemoteTestNG.main(RemoteTestNG.java:77)
]]>
            </full-stacktrace>
          </exception> <!-- java.lang.AssertionError -->
          <reporter-output>
          </reporter-output>
        </test-method> <!-- MEthod1 -->
      </class> <!-- testing.AssertDemoFailed -->
    </test> <!-- Default test -->
  </suite> <!-- Default suite -->
</testng-results>
